Workbook

Sheet Index
B6: INTRODUCTION
B7: Company Summary
B8: PEER COMPARISON
B9: Peer comparison FMCG
B10: Peer Comparison Categories
B11: Peer Comparison Charts
B12: FORECAST
B13: P&L Forecast
B14: BS Forecast
B15: Cash Flow Forecast
B16: WACC
B17: DCF
... B34: https://chatgpt.com/

Sheet Company Summary
G24: FORECASTED
B25: Key Financial Ratios | C25: FY 22 | D25: FY23 | E25: FY 24 | G25: FY 25 | H25: FY 26 | I25: FY 27 | J25: FY 28 | K25: FY 29
B26: Liquidity Ratios
B27: Current Ratio | C27: =('BS Forecast'!C11+'BS Forecast'!C13+'BS Forecast'!C14+'BS Forecast'!C15+'BS Forecast'!C16+'BS Forecast'!C10)/('BS Forecast'!C19+'BS Forecast'!C21+'BS Forecast'!C22+'BS Forecast'!C23) -> 0.93359576 | D27: =('BS Forecast'!D11+'BS Forecast'!D13+'BS Forecast'!D14+'BS Forecast'!D15+'BS Forecast'!D16+'BS Forecast'!D10)/('BS Forecast'!D19+'BS Forecast'!D21+'BS Forecast'!D22+'BS Forecast'!D23) -> 1.1496133 | E27: =('BS Forecast'!E11+'BS Forecast'!E13+'BS Forecast'!E14+'BS Forecast'!E15+'BS Forecast'!E16+'BS Forecast'!E10)/('BS Forecast'!E19+'BS Forecast'!E21+'BS Forecast'!E22+'BS Forecast'!E23) -> 1.166955 | G27: =('BS Forecast'!G11+'BS Forecast'!G13+'BS Forecast'!G14+'BS Forecast'!G15+'BS Forecast'!G16+'BS Forecast'!G10)/('BS Forecast'!G19+'BS Forecast'!G21+'BS Forecast'!G22+'BS Forecast'!G23) -> 1.2986097 | H27: =('BS Forecast'!H11+'BS Forecast'!H13+'BS Forecast'!H14+'BS Forecast'!H15+'BS Forecast'!H16+'BS Forecast'!H10)/('BS Forecast'!H19+'BS Forecast'!H21+'BS Forecast'!H22+'BS Forecast'!H23) -> 1.4309316 | I27: =('BS Forecast'!I11+'BS Forecast'!I13+'BS Forecast'!I14+'BS Forecast'!I15+'BS Forecast'!I16+'BS Forecast'!I10)/('BS Forecast'!I19+'BS Forecast'!I21+'BS Forecast'!I22+'BS Forecast'!I23) -> 1.5644417 | J27: =('BS Forecast'!J11+'BS Forecast'!J13+'BS Forecast'!J14+'BS Forecast'!J15+'BS Forecast'!J16+'BS Forecast'!J10)/('BS Forecast'!J19+'BS Forecast'!J21+'BS Forecast'!J22+'BS Forecast'!J23) -> 1.696774 | K27: =('BS Forecast'!K11+'BS Forecast'!K13+'BS Forecast'!K14+'BS Forecast'!K15+'BS Forecast'!K16+'BS Forecast'!K10)/('BS Forecast'!K19+'BS Forecast'!K21+'BS Forecast'!K22+'BS Forecast'!K23) -> 1.8256925
B28: Quick ratio | C28: =('BS Forecast'!C11+'BS Forecast'!C14+'BS Forecast'!C15+'BS Forecast'!C16+'BS Forecast'!C10)/('BS Forecast'!C19+'BS Forecast'!C21+'BS Forecast'!C22+'BS Forecast'!C23) -> 0.60945006 | D28: =('BS Forecast'!D11+'BS Forecast'!D14+'BS Forecast'!D15+'BS Forecast'!D16+'BS Forecast'!D10)/('BS Forecast'!D19+'BS Forecast'!D21+'BS Forecast'!D22+'BS Forecast'!D23) -> 0.87015588 | E28: =('BS Forecast'!E11+'BS Forecast'!E14+'BS Forecast'!E15+'BS Forecast'!E16+'BS Forecast'!E10)/('BS Forecast'!E19+'BS Forecast'!E21+'BS Forecast'!E22+'BS Forecast'!E23) -> 0.8892845 | G28: =('BS Forecast'!G11+'BS Forecast'!G14+'BS Forecast'!G15+'BS Forecast'!G16+'BS Forecast'!G10)/('BS Forecast'!G19+'BS Forecast'!G21+'BS Forecast'!G22+'BS Forecast'!G23) -> 0.99469903 | H28: =('BS Forecast'!H11+'BS Forecast'!H14+'BS Forecast'!H15+'BS Forecast'!H16+'BS Forecast'!H10)/('BS Forecast'!H19+'BS Forecast'!H21+'BS Forecast'!H22+'BS Forecast'!H23) -> 1.1141937 | I28: =('BS Forecast'!I11+'BS Forecast'!I14+'BS Forecast'!I15+'BS Forecast'!I16+'BS Forecast'!I10)/('BS Forecast'!I19+'BS Forecast'!I21+'BS Forecast'!I22+'BS Forecast'!I23) -> 1.2364085 | J28: =('BS Forecast'!J11+'BS Forecast'!J14+'BS Forecast'!J15+'BS Forecast'!J16+'BS Forecast'!J10)/('BS Forecast'!J19+'BS Forecast'!J21+'BS Forecast'!J22+'BS Forecast'!J23) -> 1.3591044 | K28: =('BS Forecast'!K11+'BS Forecast'!K14+'BS Forecast'!K15+'BS Forecast'!K16+'BS Forecast'!K10)/('BS Forecast'!K19+'BS Forecast'!K21+'BS Forecast'!K22+'BS Forecast'!K23) -> 1.4801218
B29: Solvency Ratios
B30: Debt Ratio | C30: ='BS Forecast'!C24/'BS Forecast'!C17 -> 0.6575056 | D30: ='BS Forecast'!D24/'BS Forecast'!D17 -> 0.6317457 | E30: ='BS Forecast'!E24/'BS Forecast'!E17 -> 0.57859426 | G30: ='BS Forecast'!G24/'BS Forecast'!G17 -> 0.5238762 | H30: ='BS Forecast'!H24/'BS Forecast'!H17 -> 0.48121907 | I30: ='BS Forecast'!I24/'BS Forecast'!I17 -> 0.44348722 | J30: ='BS Forecast'!J24/'BS Forecast'!J17 -> 0.410149 | K30: ='BS Forecast'!K24/'BS Forecast'!K17 -> 0.38070197
B31: Interest Coverage Ratio | C31: ='P&L Forecast'!C16/-'P&L Forecast'!C17 -> 17.073131 | D31: ='P&L Forecast'!D16/-'P&L Forecast'!D17 -> 17.85918 | E31: ='P&L Forecast'!E16/-'P&L Forecast'!E17 -> 19.879392 | G31: ='P&L Forecast'!G16/-'P&L Forecast'!G17 -> 35.367893 | H31: ='P&L Forecast'!H16/-'P&L Forecast'!H17 -> 39.280177 | I31: ='P&L Forecast'!I16/-'P&L Forecast'!I17 -> 44.147364 | J31: ='P&L Forecast'!J16/-'P&L Forecast'!J17 -> 50.378179 | K31: ='P&L Forecast'!K16/-'P&L Forecast'!K17 -> 58.653944
B32: Profitablitiy Ratios
B33: Net Profit Margin | C33: ='P&L Forecast'!C21/'P&L Forecast'!C10 -> 0.11675655 | D33: ='P&L Forecast'!D21/'P&L Forecast'!D10 -> 0.13506526 | E33: ='P&L Forecast'!E21/'P&L Forecast'!E10 -> 0.12698377 | F33: ='P&L Forecast'!F21/'P&L Forecast'!F10 -> #DIV/0! | G33: ='P&L Forecast'!G21/'P&L Forecast'!G10 -> 0.13038028 | H33: ='P&L Forecast'!H21/'P&L Forecast'!H10 -> 0.13057823 | I33: ='P&L Forecast'!I21/'P&L Forecast'!I10 -> 0.13077268 | J33: ='P&L Forecast'!J21/'P&L Forecast'!J10 -> 0.1309641 | K33: ='P&L Forecast'!K21/'P&L Forecast'!K10 -> 0.13115299
B34: Gross profit Margin | C34: ='P&L Forecast'!C12/'P&L Forecast'!C10 -> 0.38273038 | D34: ='P&L Forecast'!D12/'P&L Forecast'!D10 -> 0.40303213 | E34: ='P&L Forecast'!E12/'P&L Forecast'!E10 -> 0.42498166 | F34: ='P&L Forecast'!F12/'P&L Forecast'!F10 -> #DIV/0! | G34: ='P&L Forecast'!G12/'P&L Forecast'!G10 -> 0.42 | H34: ='P&L Forecast'!H12/'P&L Forecast'!H10 -> 0.42 | I34: ='P&L Forecast'!I12/'P&L Forecast'!I10 -> 0.42 | J34: ='P&L Forecast'!J12/'P&L Forecast'!J10 -> 0.42 | K34: ='P&L Forecast'!K12/'P&L Forecast'!K10 -> 0.42
B35: EBIT Margin | C35: ='P&L Forecast'!C16/'P&L Forecast'!C10 -> 0.16594361 | D35: ='P&L Forecast'!D16/'P&L Forecast'!D10 -> 0.17471294 | E35: ='P&L Forecast'!E16/'P&L Forecast'!E10 -> 0.18356338 | G35: ='P&L Forecast'!G16/'P&L Forecast'!G10 -> 0.18131614 | H35: ='P&L Forecast'!H16/'P&L Forecast'!H10 -> 0.18106669 | I35: ='P&L Forecast'!I16/'P&L Forecast'!I10 -> 0.18081557 | J35: ='P&L Forecast'!J16/'P&L Forecast'!J10 -> 0.18056266 | K35: ='P&L Forecast'!K16/'P&L Forecast'!K10 -> 0.18030786
B36: EBT Margin | C36: ='P&L Forecast'!C19/'P&L Forecast'!C10 -> 0.15622403 | D36: ='P&L Forecast'!D19/'P&L Forecast'!D10 -> 0.17930856 | E36: ='P&L Forecast'!E19/'P&L Forecast'!E10 -> 0.17415265 | G36: ='P&L Forecast'!G19/'P&L Forecast'!G10 -> 0.17618957 | H36: ='P&L Forecast'!H19/'P&L Forecast'!H10 -> 0.17645707 | I36: ='P&L Forecast'!I19/'P&L Forecast'!I10 -> 0.17671984 | J36: ='P&L Forecast'!J19/'P&L Forecast'!J10 -> 0.17697852 | K36: ='P&L Forecast'!K19/'P&L Forecast'!K10 -> 0.17723376
B37: ROA | C37: ='P&L Forecast'!C49 -> 0.22854296 | D37: ='P&L Forecast'!D49 -> 0.24764831 | E37: ='P&L Forecast'!E49 -> 0.24872653 | G37: ='P&L Forecast'!G49 -> 0.25212919 | H37: ='P&L Forecast'!H49 -> 0.24530172 | I37: ='P&L Forecast'!I49 -> 0.2386021 | J37: ='P&L Forecast'!J49 -> 0.2321057 | K37: ='P&L Forecast'!K49 -> 0.2258617
B38: ROE | C38: ='P&L Forecast'!C50 -> 0.66728962 | D38: ='P&L Forecast'!D50 -> 0.67249265 | E38: ='P&L Forecast'!E50 -> 0.59023053 | G38: ='P&L Forecast'!G50 -> 0.52954544 | H38: ='P&L Forecast'!H50 -> 0.4728426 | I38: ='P&L Forecast'!I50 -> 0.42874505 | J38: ='P&L Forecast'!J50 -> 0.39349886 | K38: ='P&L Forecast'!K50 -> 0.36470599
B39: Efficiency Ratios
B40: DPO | C40: ='BS Forecast'!C38 -> 50.722956 | D40: ='BS Forecast'!D38 -> 49.829155 | E40: ='BS Forecast'!E38 -> 57.777264 | G40: ='BS Forecast'!G38 -> 52.776458 | H40: ='BS Forecast'!H38 -> 52.776458 | I40: ='BS Forecast'!I38 -> 52.776458 | J40: ='BS Forecast'!J38 -> 52.776458 | K40: ='BS Forecast'!K38 -> 52.776458
B41: DSO | C41: ='BS Forecast'!C37 -> 6.6554269 | D41: ='BS Forecast'!D37 -> 6.3281228 | E41: ='BS Forecast'!E37 -> 7.619941 | G41: ='BS Forecast'!G37 -> 7.619941 | H41: ='BS Forecast'!H37 -> 7.619941 | I41: ='BS Forecast'!I37 -> 7.619941 | J41: ='BS Forecast'!J37 -> 7.619941 | K41: ='BS Forecast'!K37 -> 7.619941
B42: DIO | C42: ='BS Forecast'!C39 -> 53.162241 | D42: ='BS Forecast'!D39 -> 40.914612 | E42: ='BS Forecast'!E39 -> 41.064264 | G42: ='BS Forecast'!G39 -> 41.064264 | H42: ='BS Forecast'!H39 -> 41.064264 | I42: ='BS Forecast'!I39 -> 41.064264 | J42: ='BS Forecast'!J39 -> 41.064264 | K42: ='BS Forecast'!K39 -> 41.064264
B43: Asset Turnover Ratio | C43: ='P&L Forecast'!C10/'BS Forecast'!C17 -> 1.9574316 | D43: ='P&L Forecast'!D10/'BS Forecast'!D17 -> 1.8335456 | E43: ='P&L Forecast'!E10/'BS Forecast'!E17 -> 1.958727 | G43: ='P&L Forecast'!G10/'BS Forecast'!G17 -> 1.9337985 | H43: ='P&L Forecast'!H10/'BS Forecast'!H17 -> 1.8785806 | I43: ='P&L Forecast'!I10/'BS Forecast'!I17 -> 1.8245561 | J43: ='P&L Forecast'!J10/'BS Forecast'!J17 -> 1.7722848 | K43: ='P&L Forecast'!K10/'BS Forecast'!K17 -> 1.722124
B44: Valuation Ratios
B45: EPS till Date | C45: ='P&L'!C35 -> 66.598007 | D45: ='P&L'!D35 -> 88.850498 | E45: ='P&L'!E35 -> 86.404485
B46: P/E Ratio | C46: =3900/C45 -> 58.560311 | D46: =4500/D45 -> 50.646874 | E46: =5700/E45 -> 65.968798

Sheet Peer Comparison 

Sheet Peer comparison FMCG
B1: Peer Comparison Data For Related FMCG Companies
B3: Comparable FMCG companies | C3: Market Cap. (in Cr) | E3: Revenue as on 2024 (In Cr) | G3: Gross Profit as on 2024 | I3: GP%
B4: Britannia Industries | C4: 109347.02 | E4: ='P&L Forecast'!E8 -> 16186.08 | G4: ='P&L Forecast'!E12 -> 6968.08 | I4: =G4/E4 -> 0.4304983
B5: Nestle India | C5: 205943.98 | E5: 19515 | G5: 11067 | I5: =G5/E5 -> 0.56710223
B6: Hindustan unilever ltd | C6: 503364.67 | E6: 60469 | G6: 32115 | I6: =G6/E6 -> 0.53109858
B7: Dabur India | C7: 85797 | E7: 9136 | G7: 4625 | I7: =G7/E7 -> 0.50623905
B8: Godrej Consumer | C8: 101651 | E8: 8411 | G8: =5338 -> 5338 | I8: =G8/E8 -> 0.63464511
B10: Ratios | C10: EPS | D10: ROA | E10: ROE | F10: Net Trading Cycle | H10: ROCE %
B11: Britannia Industries | C11: ='P&L'!E35 -> 86.404485 | D11: ='P&L Forecast'!E49 -> 0.24872653 | E11: ='P&L Forecast'!E50 -> 0.59023053 | F11: ='BS Forecast'!E40 -> -9.0930588 | H11: 0.489
B12: Nestle India | C12: 40.79 | D12: 0.38 | E12: 1.35 | F12: -24 | H12: 1.69
B13: Hindustan unilever ltd | C13: 43.05 | D13: 0.1331 | E13: 0.201 | F13: -71 | H13: 0.272
B14: Dabur India | C14: 8.52 | D14: 0.1429 | E14: 0.229 | F14: -58 | H14: 0.281
B15: Godrej Consumer | C15: 6.33 | D15: 0.05 | E15: 0.128 | F15: -2 | H15: 0.241
B17: Revenue Growth Comparison YoY | C17: 2019 | D17: 2020 | E17: 2021 | F17: 2022 | G17: 2023 | H17: 2024
B18: Britannia Industries | C18: 10482 | D18: 10987 | E18: 12379 | F18: 13372 | G18: 15618 | H18: =E4 -> 16186.08
B19: YoY Growth Revenue | D19: =D18/C18-1 -> 0.048177829 | E19: =E18/D18-1 -> 0.12669519 | F19: =F18/E18-1 -> 0.080216496 | G19: =G18/F18-1 -> 0.16796291 | H19: =H18/G18-1 -> 0.036373415
B20: Nestle India | C20: 12369 | D20: 13350 | E20: 14741 | F20: 16897 | G20: 19126 | H20: =E5 -> 19515
B21: YoY Growth Revenue | D21: =D20/C20-1 -> 0.079311181 | E21: =E20/D20-1 -> 0.10419476 | F21: =F20/E20-1 -> 0.14625873 | G21: =G20/F20-1 -> 0.13191691 | H21: =H20/G20-1 -> 0.020338806
B22: Hindustan unilever ltd | C22: 38224 | D22: 38785 | E22: 45996 | F22: 51193 | G22: 59144 | H22: =E6 -> 60469
B23: YoY Growth Revenue | D23: =D22/C22-1 -> 0.014676643 | E23: =E22/D22-1 -> 0.18592239 | F23: =F22/E22-1 -> 0.11298809 | G23: =G22/F22-1 -> 0.1553142 | H23: =H22/G22-1 -> 0.022402949
B24: Dabur India | C24: 6273 | D24: 6310 | E24: 7185 | F24: 8180 | G24: 8684 | H24: 9136
B25: YoY Growth Revenue | D25: =D24/C24-1 -> 0.0058982943 | E25: =E24/D24-1 -> 0.13866878 | F25: =F24/E24-1 -> 0.13848295 | G25: =G24/F24-1 -> 0.061613692 | H25: =H24/G24-1 -> 0.052049747
B26: Godrej Consumer | C26: 5679 | D26: 5474 | E26: 6254 | F26: 6952 | G26: 7667 | H26: =E8 -> 8411
B27: YoY Growth Revenue | D27: =D26/C26-1 -> -0.036097905 | E27: =E26/D26-1 -> 0.14249178 | F27: =F26/E26-1 -> 0.11160857 | G27: =G26/F26-1 -> 0.1028481 | H27: =H26/G26-1 -> 0.097039259

Sheet Peer Comparison Categories
B1: Peer Comparison According to Britannia Categories
B3: Revenue Distribution Of britannia | C3: % of Revenue | D3: In Crores | F3: Dairy Products
B4: Biscuits | C4: 0.776 | D4: =C4*$D$7 -> 12560.398 | F4: Cheese | G4: % of Market Share | H4: in Crores
B5: Dairy Products | C5: 0.124 | D5: =C5*$D$7 -> 2007.0739 | F5: Amul | G5: 0.9 | H5: =G5*$H$11 -> 8001
B6: Others | C6: 0.1 | D6: =C6*$D$7 -> 1618.608 | F6: Britannia | G6: 0.05 | H6: =G6*$H$11 -> 444.5
B7: Total | C7: 1 | D7: ='P&L Forecast'!E8 -> 16186.08 | F7: Parag Milk Foods(Go Cheese) | G7: 0.02 | H7: =G7*$H$11 -> 177.8
F8: Mother Dairy | G8: 0.01 | H8: =G8*$H$11 -> 88.9
F9: Karnataka Milk Federation (Nandini) | G9: 0.01 | H9: =G9*$H$11 -> 88.9
F10: Others | G10: 0.01 | H10: =G10*$H$11 -> 88.9
B11: Biscuit Industry | F11: Total Market Size of Cheese Industry | G11: 1 | H11: 8890
B12: Market Big Players | C12: % of market share | D12: In Crores | F12: Flavoured Milk | G12: % of Market Share | H12: in Crores
B13: Britannia | C13: 0.31 | D13: =C13*$D$19 -> 12563.99 | F13: Amul | G13: 0.25 | H13: =G13*$H$19 -> 1582.5
B14: Parle | C14: 0.29 | D14: =C14*$D$19 -> 11753.41 | F14: Mother Dairy | G14: 0.2 | H14: =G14*$H$19 -> 1266
B15: ITC | C15: 0.12 | D15: =C15*$D$19 -> 4863.48 | F15: Britannia | G15: 0.15 | H15: =G15*$H$19 -> 949.5
B16: Priya gold | C16: 0.05 | D16: =C16*$D$19 -> 2026.45 | F16: Parle Agro | G16: 0.1 | H16: =G16*$H$19 -> 633
B17: Anmol Industries | C17: 0.04 | D17: =C17*$D$19 -> 1621.16 | F17: CavinKare | G17: 0.05 | H17: =G17*$H$19 -> 316.5
B18: Others | C18: 0.19 | D18: =C18*$D$19 -> 7700.51 | F18: Others | G18: 0.25 | H18: =G18*$H$19 -> 1582.5
B19: Total market Size of Biscuit Industry | C19: 1 | D19: 40529 | F19: Total Market Size of Flavoured Milk Industry | G19: 1 | H19: 6330
B22: *Britannia is also a major player in Cakes and Bread market but Market Share and Other Details are not Available.

Sheet Peer Comparison Charts
B1: Peer Comparison Charts

Sheet FORECASTS 

Sheet P&L Forecast
B1: Income Statement
C2: 2
C6: ACTUAL | G6: FORECAST | L6: TRENDS
B7: (in crores) | C7: 44651 | D7: 45016 | E7: 45382 | G7: 45747 | H7: 46112 | I7: 46477 | J7: 46843 | K7: 47208
B8: Revenue from operations | C8: =SUMIF('P&L'!$B$4:$B$28,'P&L Forecast'!$B8,'P&L'!C$4:C$28) -> 13371.62 | D8: =SUMIF('P&L'!$B$4:$B$28,'P&L Forecast'!$B8,'P&L'!D$4:D$28) -> 15618.42 | E8: =SUMIF('P&L'!$B$4:$B$28,'P&L Forecast'!$B8,'P&L'!E$4:E$28) -> 16186.08 | G8: =E8*(1+G$23) -> 16833.523 | H8: =G8*(1+H$23) -> 17506.864 | I8: =H8*(1+I$23) -> 18207.139 | J8: =I8*(1+J$23) -> 18935.424 | K8: =J8*(1+K$23) -> 19692.841
B9: Other Income | C9: =SUMIF('P&L'!$B$4:$B$28,'P&L Forecast'!$B9,'P&L'!C$4:C$28) -> 359.43 | D9: =SUMIF('P&L'!$B$4:$B$28,'P&L Forecast'!$B9,'P&L'!D$4:D$28) -> 220.59 | E9: =SUMIF('P&L'!$B$4:$B$28,'P&L Forecast'!$B9,'P&L'!E$4:E$28) -> 210.11 | G9: =E9*(1+G$27) -> 199.6045 | H9: =G9*(1+H27) -> 189.62427 | I9: =H9*(1+I$27) -> 180.14306 | J9: =I9*(1+J27) -> 171.13591 | K9: =J9*(1+K$27) -> 162.57911
B10: Total Revenues | C10: =SUM(C8:C9) -> 13731.05 | D10: =SUM(D8:D9) -> 15839.01 | E10: =SUM(E8:E9) -> 16396.19 | G10: =SUM(G8:G9) -> 17033.128 | H10: =SUM(H8:H9) -> 17696.488 | I10: =SUM(I8:I9) -> 18387.282 | J10: =SUM(J8:J9) -> 19106.56 | K10: =SUM(K8:K9) -> 19855.42
B11: Cost Of Goods Sold | C11: =-SUMIF('P&L'!$B$4:$B$28,'P&L Forecast'!$B11,'P&L'!C$4:C$28) -> -8475.76 | D11: =-SUMIF('P&L'!$B$4:$B$28,'P&L Forecast'!$B11,'P&L'!D$4:D$28) -> -9455.38 | E11: =-SUMIF('P&L'!$B$4:$B$28,'P&L Forecast'!$B11,'P&L'!E$4:E$28) -> -9428.11 | G11: =G10*G31 -> -9879.2141 | H11: =H10*H31 -> -10263.963 | I11: =I10*I31 -> -10664.623 | J11: =J10*J31 -> -11081.805 | K11: =K10*K31 -> -11516.144
B12: Gross Profit | C12: =SUM(C10:C11) -> 5255.29 | D12: =SUM(D10:D11) -> 6383.63 | E12: =SUM(E10:E11) -> 6968.08 | G12: =SUM(G10:G11) -> 7153.9136 | H12: =SUM(H10:H11) -> 7432.5251 | I12: =SUM(I10:I11) -> 7722.6583 | J12: =SUM(J10:J11) -> 8024.7553 | K12: =SUM(K10:K11) -> 8339.2765
B13: Operating and other expenses | C13: ='P&L'!C14+'P&L'!C15 -> -2806.7 | D13: ='P&L'!D14+'P&L'!D15 -> -3421.25 | E13: ='P&L'!E14+'P&L'!E15 -> -3687.15 | G13: =G10*G35 -> -3747.2881 | H13: =H10*H35 -> -3893.2274 | I13: =I10*I35 -> -4045.202 | J13: =J10*J35 -> -4203.4432 | K13: =K10*K35 -> -4368.1925
B14: EBITDA | C14: =C12+C13 -> 2448.59 | D14: =D12+D13 -> 2962.38 | E14: =E12+E13 -> 3280.93 | G14: =G12+G13 -> 3406.6255 | H14: =H12+H13 -> 3539.2977 | I14: =I12+I13 -> 3677.4564 | J14: =J12+J13 -> 3821.312 | K14: =K12+K13 -> 3971.0841
B15: D&A | C15: ='P&L'!C17 -> -170.01 | D15: ='P&L'!D17 -> -195.1 | E15: ='P&L'!E17 -> -271.19 | G15: ='PP&E schedule'!F6 -> -318.24457 | H15: ='PP&E schedule'!G6 -> -335.05319 | I15: ='PP&E schedule'!H6 -> -352.74957 | J15: ='PP&E schedule'!I6 -> -371.38062 | K15: ='PP&E schedule'!J6 -> -390.9957
B16: EBIT | C16: =SUM(C14:C15) -> 2278.58 | D16: =SUM(D14:D15) -> 2767.28 | E16: =SUM(E14:E15) -> 3009.74 | G16: =SUM(G14:G15) -> 3088.381 | H16: =SUM(H14:H15) -> 3204.2445 | I16: =SUM(I14:I15) -> 3324.7068 | J16: =SUM(J14:J15) -> 3449.9314 | K16: =SUM(K14:K15) -> 3580.0884
B17: Interest Expenses | C17: =SUMIF('P&L'!$B$4:$B$28,'P&L Forecast'!$B17,'P&L'!C$4:C$28) -> -133.46 | D17: =SUMIF('P&L'!$B$4:$B$28,'P&L Forecast'!$B17,'P&L'!D$4:D$28) -> -154.95 | E17: =SUMIF('P&L'!$B$4:$B$28,'P&L Forecast'!$B17,'P&L'!E$4:E$28) -> -151.4 | G17: ='financial liabilites'!C19 -> -87.3216 | H17: ='financial liabilites'!D19 -> -81.574084 | I17: ='financial liabilites'!E19 -> -75.309292 | J17: ='financial liabilites'!F19 -> -68.480669 | K17: ='financial liabilites'!G19 -> -61.03747
B18: Exceptional items | C18: =SUMIF('P&L'!$B$4:$B$28,'P&L Forecast'!$B18,'P&L'!C$4:C$28) -> 0 | D18: =SUMIF('P&L'!$B$4:$B$28,'P&L Forecast'!$B18,'P&L'!D$4:D$28) -> 227.74 | E18: =SUMIF('P&L'!$B$4:$B$28,'P&L Forecast'!$B18,'P&L'!E$4:E$28) -> -2.9 | G18: =G10*G39 -> 0 | H18: =H10*H39 -> 0 | I18: =I10*I39 -> 0 | J18: =J10*J39 -> 0 | K18: =K10*K39 -> 0
B19: Profit Before Tax | C19: =SUM(C16:C18) -> 2145.12 | D19: =SUM(D16:D18) -> 2840.07 | E19: =SUM(E16:E18) -> 2855.44 | G19: =SUM(G16:G18) -> 3001.0594 | H19: =SUM(H16:H18) -> 3122.6704 | I19: =SUM(I16:I18) -> 3249.3975 | J19: =SUM(J16:J18) -> 3381.4507 | K19: =SUM(K16:K18) -> 3519.0509
B20: Tax expense | C20: =-'P&L'!C25 -> -541.93 | D20: =-'P&L'!D25 -> -700.77 | E20: =-'P&L'!E25 -> -773.39 | G20: =G19*G43 -> -780.27543 | H20: =H19*H43 -> -811.89431 | I20: =I19*I43 -> -844.84335 | J20: =J19*J43 -> -879.17719 | K20: =K19*K43 -> -914.95323
B21: Profit After Tax | C21: =C19+C20 -> 1603.19 | D21: =D19+D20 -> 2139.3 | E21: =E19+E20 -> 2082.05 | G21: =G19+G20 -> 2220.7839 | H21: =H19+H20 -> 2310.7761 | I21: =I19+I20 -> 2404.5541 | J21: =J19+J20 -> 2502.2735 | K21: =K19+K20 -> 2604.0977
B23: Y-o-Y Growth (Revenues) | D23: =(D10/C10)-1 -> 0.15351776 | E23: =(E10/D10)-1 -> 0.035177704 | G23: =CHOOSE($C$2,G$24,G$25,G$26) -> 0.04 | H23: =CHOOSE($C$2,H$24,H$25,H$26) -> 0.04 | I23: =CHOOSE($C$2,I$24,I$25,I$26) -> 0.04 | J23: =CHOOSE($C$2,J$24,J$25,J$26) -> 0.04 | K23: =CHOOSE($C$2,K$24,K$25,K$26) -> 0.04
B24: best case | G24: 0.06 | H24: 0.06 | I24: 0.06 | J24: 0.06 | K24: 0.06
B25: base case | G25: 0.04 | H25: 0.04 | I25: 0.04 | J25: 0.04 | K25: 0.04
B26: worst case | G26: 0.02 | H26: 0.02 | I26: 0.02 | J26: 0.02 | K26: 0.02
B27: Y-o-Y Growth (Other Revenues) | D27: =(D9/C9)-1 -> -0.38627827 | E27: =(E9/D9)-1 -> -0.047508953 | G27: =CHOOSE($C$2,G$28,G29,G30) -> -0.05 | H27: =CHOOSE($C$2,H$28,H29,H30) -> -0.05 | I27: =CHOOSE($C$2,I$28,I29,I30) -> -0.05 | J27: =CHOOSE($C$2,J$28,J29,J30) -> -0.05 | K27: =CHOOSE($C$2,K$28,K29,K30) -> -0.05
B28: best case | G28: -0.03 | H28: -0.03 | I28: -0.03 | J28: -0.03 | K28: -0.03
B29: base case | G29: -0.05 | H29: -0.05 | I29: -0.05 | J29: -0.05 | K29: -0.05
B30: worst case | G30: -0.07 | H30: -0.07 | I30: -0.07 | J30: -0.07 | K30: -0.07
B31: COGS as a % of Revenues | C31: =C11/C10 -> -0.61726962 | D31: =D11/D10 -> -0.59696787 | E31: =E11/E10 -> -0.57501834 | G31: =CHOOSE($C$2,G32,G33,G34) -> -0.58 | H31: =CHOOSE($C$2,H32,H33,H34) -> -0.58 | I31: =CHOOSE($C$2,I32,I33,I34) -> -0.58 | J31: =CHOOSE($C$2,J32,J33,J34) -> -0.58 | K31: =CHOOSE($C$2,K32,K33,K34) -> -0.58
B32: best case | G32: -0.56 | H32: -0.56 | I32: -0.56 | J32: -0.56 | K32: -0.56
B33: base case | G33: -0.58 | H33: -0.58 | I33: -0.58 | J33: -0.58 | K33: -0.58
B34: worst case | G34: -0.6 | H34: -0.6 | I34: -0.6 | J34: -0.6 | K34: -0.6
B35: Opex and other Expenses as a % of Revenue | C35: =C13/C10 -> -0.20440534 | D35: =D13/D10 -> -0.21600151 | E35: =E13/E10 -> -0.22487846 | G35: =CHOOSE($C$2,G36,G37,G38) -> -0.22 | H35: =CHOOSE($C$2,H36,H37,H38) -> -0.22 | I35: =CHOOSE($C$2,I36,I37,I38) -> -0.22 | J35: =CHOOSE($C$2,J36,J37,J38) -> -0.22 | K35: =CHOOSE($C$2,K36,K37,K38) -> -0.22
B36: best case | G36: -0.2 | H36: -0.2 | I36: -0.2 | J36: -0.2 | K36: -0.2
B37: base case | G37: -0.22 | H37: -0.22 | I37: -0.22 | J37: -0.22 | K37: -0.22
B38: worst case | G38: -0.24 | H38: -0.24 | I38: -0.24 | J38: -0.24 | K38: -0.24
B39: Exceptional Items as % of Revenue | C39: =C18/C10 -> 0 | D39: =D18/D10 -> 0.014378424 | E39: =E18/E10 -> -0.00017687036 | G39: =CHOOSE($C$2,G40,G41,G42) -> 0 | H39: =CHOOSE($C$2,H40,H41,H42) -> 0 | I39: =CHOOSE($C$2,I40,I41,I42) -> 0 | J39: =CHOOSE($C$2,J40,J41,J42) -> 0 | K39: =CHOOSE($C$2,K40,K41,K42) -> 0
B40: best case | G40: 0 | H40: 0 | I40: 0 | J40: 0 | K40: 0
B41: base case | G41: 0 | H41: 0 | I41: 0 | J41: 0 | K41: 0
B42: worst case | G42: 0 | H42: 0 | I42: 0 | J42: 0 | K42: 0
B43: Tax as a % of Profit Before Tax(PBT) | C43: =C20/C19 -> -0.25263389 | D43: =D20/D19 -> -0.24674392 | E43: =E20/E19 -> -0.27084793 | G43: =CHOOSE($C$2,G44,G45,G46) -> -0.26 | H43: =CHOOSE($C$2,H44,H45,H46) -> -0.26 | I43: =CHOOSE($C$2,I44,I45,I46) -> -0.26 | J43: =CHOOSE($C$2,J44,J45,J46) -> -0.26 | K43: =CHOOSE($C$2,K44,K45,K46) -> -0.26
B44: best case | G44: -0.24 | H44: -0.24 | I44: -0.24 | J44: -0.24 | K44: -0.24
...

Sheet BS Forecast
B1: Balance sheet
C3: ACTUAL | G3: FORECAST
B4: (in crores) | C4: 44651 | D4: 45016 | E4: 45382 | G4: 45747 | H4: 46112 | I4: 46477 | J4: 46843 | K4: 47208
B5: Other Intangible assets | C5: =BS!C9 -> 15.6 | D5: =BS!D9 -> 12.75 | E5: =BS!E9 -> 9.38 | G5: =$E$5 -> 9.38 | H5: =$E$5 -> 9.38 | I5: =$E$5 -> 9.38 | J5: =$E$5 -> 9.38 | K5: =$E$5 -> 9.38
B6: Investment property | C6: =BS!C8 -> 34.42 | D6: =BS!D8 -> 60.5 | E6: =BS!E8 -> 46.75 | G6: =$E$6 -> 46.75 | H6: =$E$6 -> 46.75 | I6: =$E$6 -> 46.75 | J6: =$E$6 -> 46.75 | K6: =$E$6 -> 46.75
B7: PP&E | C7: =BS!C6 -> 1327.41 | D7: =BS!D6 -> 2220.21 | E7: =BS!E6 -> 2365.04 | G7: ='PP&E schedule'!F8 -> 2489.9535 | H7: ='PP&E schedule'!G8 -> 2621.4645 | I7: ='PP&E schedule'!H8 -> 2759.9214 | J7: ='PP&E schedule'!I8 -> 2905.6912 | K7: ='PP&E schedule'!J8 -> 3059.1601
B8: CWIP | C8: =BS!C7 -> 535.27 | D8: =BS!D7 -> 104.47 | E8: =BS!E7 -> 187.48 | G8: =$E$8 -> 187.48 | H8: =$E$8 -> 187.48 | I8: =$E$8 -> 187.48 | J8: =$E$8 -> 187.48 | K8: =$E$8 -> 187.48
B9: Non Current Financial assets | C9: =SUM(BS!C11:C13) -> 1334.74 | D9: =SUM(BS!D11:D13) -> 1688.14 | E9: =SUM(BS!E11:E13) -> 1093.29 | G9: =$E$9 -> 1093.29 | H9: =$E$9 -> 1093.29 | I9: =$E$9 -> 1093.29 | J9: =$E$9 -> 1093.29 | K9: =$E$9 -> 1093.29
B10: Current Financial Assets | C10: =BS!C21+BS!C24+BS!C25+BS!C26 -> 1969.19 | D10: =BS!D21+BS!D24+BS!D25+BS!D26 -> 2863.13 | E10: =BS!E21+BS!E24+BS!E25+BS!E26 -> 2728.91 | G10: =$E$10 -> 2728.91 | H10: =$E$10 -> 2728.91 | I10: =$E$10 -> 2728.91 | J10: =$E$10 -> 2728.91 | K10: =$E$10 -> 2728.91
B11: Other Current Assets | C11: =BS!C27 -> 120.29 | D11: =BS!D27 -> 163.08 | E11: =BS!E27 -> 121.05 | G11: =G32*'P&L Forecast'!G10 -> 150.11493 | H11: =H32*'P&L Forecast'!H10 -> 156.42732 | I11: =I32*'P&L Forecast'!I10 -> 148.89955 | J11: =J32*'P&L Forecast'!J10 -> 168.63996 | K11: =K32*'P&L Forecast'!K10 -> 170.42924
B12: Other Non Current Assets | C12: =BS!C16+BS!C14+BS!C15 -> 162.45 | D12: =BS!D16+BS!D14+BS!D15 -> 131.69 | E12: =BS!E16+BS!E14+BS!E15 -> 149.19 | G12: =G31*'P&L Forecast'!G10 -> 166.04005 | H12: =H31*'P&L Forecast'!H10 -> 172.50654 | I12: =I31*'P&L Forecast'!I10 -> 179.24044 | J12: =J31*'P&L Forecast'!J10 -> 186.25201 | K12: =K31*'P&L Forecast'!K10 -> 193.55195
B13: Inventory | C13: =BS!C19 -> 1251.64 | D13: =BS!D19 -> 1074.62 | E13: =BS!E19 -> 1075.44 | G13: =-(G39*'P&L Forecast'!G11)/360 -> 1126.8963 | H13: =-(H39*'P&L Forecast'!H11)/360 -> 1170.7836 | I13: =-(I39*'P&L Forecast'!I11)/360 -> 1216.4859 | J13: =-(J39*'P&L Forecast'!J11)/360 -> 1264.0727 | K13: =-(K39*'P&L Forecast'!K11)/360 -> 1313.6166
B14: Trade receivable | C14: =BS!C22 -> 253.85 | D14: =BS!D22 -> 278.42 | E14: =BS!E22 -> 347.05 | G14: =(G37*'P&L Forecast'!G10)/360 -> 360.53174 | H14: =(H37*'P&L Forecast'!H10)/360 -> 374.57277 | I14: =(I37*'P&L Forecast'!I10)/360 -> 389.19445 | J14: =(J37*'P&L Forecast'!J10)/360 -> 404.41906 | K14: =(K37*'P&L Forecast'!K10)/360 -> 420.26981
B15: Asset Held for sale | C15: =BS!C28 -> 0 | D15: =BS!D28 -> 32.36 | E15: =BS!E28 -> 6.41 | G15: =0 -> 0 | H15: =0 -> 0 | I15: =0 -> 0 | J15: =0 -> 0 | K15: =0 -> 0
B16: Cash and Cash equivalents | C16: ='Cash Flow'!C8 -> 9.97 | D16: ='Cash Flow'!D8 -> 9.09 | E16: ='Cash Flow'!E8 -> 240.85 | G16: =E16+'Cash Flow Forecast'!F25 -> 448.77278 | H16: =G16+'Cash Flow Forecast'!G25 -> 858.57349 | I16: =H16+'Cash Flow Forecast'!H25 -> 1318.1221 | J16: =I16+'Cash Flow Forecast'!I25 -> 1785.8654 | K16: =J16+'Cash Flow Forecast'!J25 -> 2306.7736
B17: Total Assets | C17: =SUM(C5:C16) -> 7014.83 | D17: =SUM(D5:D16) -> 8638.46 | E17: =SUM(E5:E16) -> 8370.84 | G17: =SUM(G5:G16) -> 8808.1193 | H17: =SUM(H5:H16) -> 9420.1382 | I17: =SUM(I5:I16) -> 10077.674 | J17: =SUM(J5:J16) -> 10780.75 | K17: =SUM(K5:K16) -> 11529.611
B19: Current Financial liabilities | C19: =SUM(BS!C45,BS!C46,BS!C50) -> 2038.31 | D19: =SUM(BS!D45,BS!D46,BS!D50) -> 1804.56 | E19: =SUM(BS!E45,BS!E46,BS!E50) -> 1572.11 | G19: =E19*(1+G33) -> 1414.899 | H19: =G19*(1+H33) -> 1273.4091 | I19: =H19*(1+I33) -> 1146.0682 | J19: =I19*(1+J33) -> 1031.4614 | K19: =J19*(1+K33) -> 928.31523
B20: Non Current Financial liabilities | C20: =BS!C42 -> 750.94 | D20: =BS!D42 -> 1611.93 | E20: =BS!E42 -> 970.24 | G20: ='financial liabilites'!F9 -> 906.37872 | H20: ='financial liabilites'!G9 -> 836.76992 | I20: ='financial liabilites'!H9 -> 760.89632 | J20: ='financial liabilites'!I9 -> 678.19411 | K20: ='financial liabilites'!J9 -> 588.0487
B21: Trade payable | C21: =SUM(BS!C48:C49) -> 1194.21 | D21: =SUM(BS!D48:D49) -> 1308.76 | E21: =SUM(BS!E48:E49) -> 1513.14 | G21: =-(G38*'P&L Forecast'!G11)/360 -> 1448.3054 | H21: =-(H38*'P&L Forecast'!H11)/360 -> 1504.7101 | I21: =-(I38*'P&L Forecast'!I11)/360 -> 1563.4474 | J21: =-(J38*'P&L Forecast'!J11)/360 -> 1624.6067 | K21: =-(K38*'P&L Forecast'!K11)/360 -> 1688.2813
B22: Other liabilities | C22: =BS!C51+BS!C53 -> 177.67 | D22: =BS!D51+BS!D53 -> 223.2 | E22: =BS!E51+BS!E53 -> 236.64 | G22: =G34*'P&L Forecast'!G10 -> 235.41882 | H22: =H34*'P&L Forecast'!H10 -> 244.58729 | I22: =I34*'P&L Forecast'!I10 -> 254.1349 | J22: =J34*'P&L Forecast'!J10 -> 264.07622 | K22: =K34*'P&L Forecast'!K10 -> 274.42639
B23: Provisions | C23: =BS!C52 -> 451.16 | D23: =BS!D52 -> 508.86 | E23: =BS!E52 -> 551.19 | G23: =E23*(1+G35) -> 609.36218 | H23: =G23*(1+H35) -> 673.6738 | I23: =H23*(1+I35) -> 744.77282 | J23: =I23*(1+J35) -> 823.37558 | K23: =J23*(1+K35) -> 910.27402
B24: Total Liabilities | C24: =SUM(C19:C23) -> 4612.29 | D24: =SUM(D19:D23) -> 5457.31 | E24: =SUM(E19:E23) -> 4843.32 | G24: =SUM(G19:G23) -> 4614.3641 | H24: =SUM(H19:H23) -> 4533.1502 | I24: =SUM(I19:I23) -> 4469.3196 | J24: =SUM(J19:J23) -> 4421.714 | K24: =SUM(K19:K23) -> 4389.3457
B26: Shareholders' Equity | C26: =BS!C35 -> 2402.54 | D26: =BS!D35 -> 3181.15 | E26: =BS!E35 -> 3527.52 | G26: ='Equity Schedule'!F10 -> 4193.7552 | H26: ='Equity Schedule'!G10 -> 4886.988 | I26: ='Equity Schedule'!H10 -> 5608.3543 | J26: ='Equity Schedule'!I10 -> 6359.0363 | K26: ='Equity Schedule'!J10 -> 7140.2656
B27: Total Liabilities and Equity | C27: =C24+C26 -> 7014.83 | D27: =D24+D26 -> 8638.46 | E27: =E24+E26 -> 8370.84 | G27: =G24+G26 -> 8808.1193 | H27: =H24+H26 -> 9420.1382 | I27: =I24+I26 -> 10077.674 | J27: =J24+J26 -> 10780.75 | K27: =K24+K26 -> 11529.611
B29: Check | C29: =C27-C17 -> 0 | D29: =D27-D17 -> 0 | E29: =E27-E17 -> 0 | G29: =G27-G17 -> 0 | H29: =H27-H17 -> 0 | I29: =I27-I17 -> 0 | J29: =J27-J17 -> 0 | K29: =K27-K17 -> 0
B31: Other Non Current Assets as a % of Revenue | C31: =C12/'P&L Forecast'!C10 -> 0.011830851 | D31: =D12/'P&L Forecast'!D10 -> 0.0083142823 | E31: =E12/'P&L Forecast'!E10 -> 0.0090990651 | G31: =AVERAGE($C$31:$E$31) -> 0.009748066 | H31: =AVERAGE($C$31:$E$31) -> 0.009748066 | I31: =AVERAGE($C$31:$E$31) -> 0.009748066 | J31: =AVERAGE($C$31:$E$31) -> 0.009748066 | K31: =AVERAGE($C$31:$E$31) -> 0.009748066
B32: Other Current Assets as a % of Revenue | C32: =C11/'P&L Forecast'!C10 -> 0.0087604371 | D32: =D11/'P&L Forecast'!D10 -> 0.010296098 | E32: =E11/'P&L Forecast'!E10 -> 0.0073828127 | G32: =AVERAGE(C32:E32) -> 0.008813116 | H32: =AVERAGE(D32:F32) -> 0.0088394554 | I32: =AVERAGE(E32:G32) -> 0.0080979643 | J32: =AVERAGE(F32:H32) -> 0.0088262857 | K32: =AVERAGE(G32:I32) -> 0.0085835119
B33: Current Fianancial Liabilties YoY | D33: =D19/C19-1 -> -0.11467834 | E33: =E19/D19-1 -> -0.12881256 | G33: -0.1 | H33: -0.1 | I33: -0.1 | J33: -0.1 | K33: -0.1
B34: Other Liabilities as a % of Revenue | C34: =C22/'P&L Forecast'!C10 -> 0.012939287 | D34: =D22/'P&L Forecast'!D10 -> 0.01409179 | E34: =E22/'P&L Forecast'!E10 -> 0.014432621 | G34: =AVERAGE($C$34:$E$34) -> 0.013821233 | H34: =AVERAGE($C$34:$E$34) -> 0.013821233 | I34: =AVERAGE($C$34:$E$34) -> 0.013821233 | J34: =AVERAGE($C$34:$E$34) -> 0.013821233 | K34: =AVERAGE($C$34:$E$34) -> 0.013821233
B35: Provision change YoY | D35: =(D23/C23)-1 -> 0.12789254 | E35: =(E23/D23)-1 -> 0.083185945 | G35: =AVERAGE($D$35:$E$35) -> 0.10553924 | H35: =AVERAGE($D$35:$E$35) -> 0.10553924 | I35: =AVERAGE($D$35:$E$35) -> 0.10553924 | J35: =AVERAGE($D$35:$E$35) -> 0.10553924 | K35: =AVERAGE($D$35:$E$35) -> 0.10553924
B37: DSO (Days Sales Outstanding) | C37: =(C14/'P&L Forecast'!C10)*360 -> 6.6554269 | D37: =(D14/'P&L Forecast'!D10)*360 -> 6.3281228 | E37: =(E14/'P&L Forecast'!E10)*360 -> 7.619941 | G37: =$E$37 -> 7.619941 | H37: =$E$37 -> 7.619941 | I37: =$E$37 -> 7.619941 | J37: =$E$37 -> 7.619941 | K37: =$E$37 -> 7.619941
B38: DPO (Days Payable Outstanding) | C38: =-(C21/'P&L Forecast'!C11)*360 -> 50.722956 | D38: =-(D21/'P&L Forecast'!D11)*360 -> 49.829155 | E38: =-(E21/'P&L Forecast'!E11)*360 -> 57.777264 | G38: =AVERAGE($C$38:$E$38) -> 52.776458 | H38: =AVERAGE($C$38:$E$38) -> 52.776458 | I38: =AVERAGE($C$38:$E$38) -> 52.776458 | J38: =AVERAGE($C$38:$E$38) -> 52.776458 | K38: =AVERAGE($C$38:$E$38) -> 52.776458
B39: DIO (Days Inventory Outstanding) | C39: =-(C13/'P&L Forecast'!C11)*360 -> 53.162241 | D39: =-(D13/'P&L Forecast'!D11)*360 -> 40.914612 | E39: =-(E13/'P&L Forecast'!E11)*360 -> 41.064264 | G39: =$E$39 -> 41.064264 | H39: =$E$39 -> 41.064264 | I39: =$E$39 -> 41.064264 | J39: =$E$39 -> 41.064264 | K39: =$E$39 -> 41.064264
B40: Net Trading cycle | C40: =C37+C39-C38 -> 9.0947126 | D40: =D37+D39-D38 -> -2.5864211 | E40: =E37+E39-E38 -> -9.0930588 | G40: =G37+G39-G38 -> -4.0922532 | H40: =H37+H39-H38 -> -4.0922532 | I40: =I37+I39-I38 -> -4.0922532 | J40: =J37+J39-J38 -> -4.0922532 | K40: =K37+K39-K38 -> -4.0922532

Sheet Cash Flow Forecast
B1: Cash Flow
C3: ACTUAL | F3: FORECAST
B4: (in crores) | C4: FY23 | D4: FY24 | F4: FY25 | G4: FY26 | H4: FY27 | I4: FY28 | J4: FY29
B5: EBIT | C5: ='P&L Forecast'!D16 -> 2767.28 | D5: ='P&L Forecast'!E16 -> 3009.74 | F5: ='P&L Forecast'!G16 -> 3088.381 | G5: ='P&L Forecast'!H16 -> 3204.2445 | H5: ='P&L Forecast'!I16 -> 3324.7068 | I5: ='P&L Forecast'!J16 -> 3449.9314 | J5: ='P&L Forecast'!K16 -> 3580.0884
B6: Operating Taxes | C6: =C5*'P&L Forecast'!D43 -> -682.80951 | D6: =D5*'P&L Forecast'!E43 -> -815.18183 | F6: =F5*'P&L Forecast'!G43 -> -802.97905 | G6: =G5*'P&L Forecast'!H43 -> -833.10357 | H6: =H5*'P&L Forecast'!I43 -> -864.42376 | I6: =I5*'P&L Forecast'!J43 -> -896.98217 | J6: =J5*'P&L Forecast'!K43 -> -930.82298
B7: NOPAT | C7: =C5+C6 -> 2084.4705 | D7: =D5+D6 -> 2194.5582 | F7: =F5+F6 -> 2285.4019 | G7: =G5+G6 -> 2371.1409 | H7: =H5+H6 -> 2460.283 | I7: =I5+I6 -> 2552.9492 | J7: =J5+J6 -> 2649.2654
B8: Add Back D&A | C8: =-'P&L Forecast'!D15 -> 195.1 | D8: =-'P&L Forecast'!E15 -> 271.19 | F8: =-'P&L Forecast'!G15 -> 318.24457 | G8: =-'P&L Forecast'!H15 -> 335.05319 | H8: =-'P&L Forecast'!I15 -> 352.74957 | I8: =-'P&L Forecast'!J15 -> 371.38062 | J8: =-'P&L Forecast'!K15 -> 390.9957
B9: Gross Cash Flow | C9: =C7+C8 -> 2279.5705 | D9: =D7+D8 -> 2465.7482 | F9: =F7+F8 -> 2603.6465 | G9: =G7+G8 -> 2706.1941 | H9: =H7+H8 -> 2813.0326 | I9: =I7+I8 -> 2924.3299 | J9: =J7+J8 -> 3040.2611
B10: Inventory | C10: =-('BS Forecast'!D13-'BS Forecast'!C13) -> 177.02 | D10: =-('BS Forecast'!E13-'BS Forecast'!D13) -> -0.82 | F10: =-('BS Forecast'!G13-'BS Forecast'!E13) -> -51.456268 | G10: =-('BS Forecast'!H13-'BS Forecast'!G13) -> -43.887342 | H10: =-('BS Forecast'!I13-'BS Forecast'!H13) -> -45.702261 | I10: =-('BS Forecast'!J13-'BS Forecast'!I13) -> -47.586806 | J10: =-('BS Forecast'!K13-'BS Forecast'!J13) -> -49.543909
B11: Trade Receiveable | C11: =-('BS Forecast'!D14-'BS Forecast'!C14) -> -24.57 | D11: =-('BS Forecast'!E14-'BS Forecast'!D14) -> -68.63 | F11: =-('BS Forecast'!G14-'BS Forecast'!E14) -> -13.481744 | G11: =-('BS Forecast'!H14-'BS Forecast'!G14) -> -14.041026 | H11: =-('BS Forecast'!I14-'BS Forecast'!H14) -> -14.621679 | I11: =-('BS Forecast'!J14-'BS Forecast'!I14) -> -15.224608 | J11: =-('BS Forecast'!K14-'BS Forecast'!J14) -> -15.850751
B12: Trade Payable | C12: ='BS Forecast'!D21-'BS Forecast'!C21 -> 114.55 | D12: ='BS Forecast'!E21-'BS Forecast'!D21 -> 204.38 | F12: ='BS Forecast'!G21-'BS Forecast'!E21 -> -64.834638 | G12: ='BS Forecast'!H21-'BS Forecast'!G21 -> 56.404724 | H12: ='BS Forecast'!I21-'BS Forecast'!H21 -> 58.737287 | I12: ='BS Forecast'!J21-'BS Forecast'!I21 -> 61.159335 | J12: ='BS Forecast'!K21-'BS Forecast'!J21 -> 63.674636
B14: Investment In Working Capital | C14: =SUM(C10:C12) -> 267 | D14: =SUM(D10:D12) -> 134.93 | F14: =SUM(F10:F12) -> -129.77265 | G14: =SUM(G10:G12) -> -1.5236443 | H14: =SUM(H10:H12) -> -1.5866532 | I14: =SUM(I10:I12) -> -1.6520792 | J14: =SUM(J10:J12) -> -1.7200243
B15: other assets | C15: =-('BS Forecast'!D12-'BS Forecast'!C12)-('BS Forecast'!D5-'BS Forecast'!C5)-('BS Forecast'!D6-'BS Forecast'!C6)-('BS Forecast'!D8-'BS Forecast'!C8)-('BS Forecast'!D15-'BS Forecast'!C15)-('BS Forecast'!D9-'BS Forecast'!C9)-('BS Forecast'!D10-'BS Forecast'!C10)-('BS Forecast'!D11-'BS Forecast'!C11) -> -884.16 | D15: =-('BS Forecast'!E12-'BS Forecast'!D12)-('BS Forecast'!E5-'BS Forecast'!D5)-('BS Forecast'!E6-'BS Forecast'!D6)-('BS Forecast'!E8-'BS Forecast'!D8)-('BS Forecast'!E15-'BS Forecast'!D15)-('BS Forecast'!E9-'BS Forecast'!D9)-('BS Forecast'!E10-'BS Forecast'!D10)-('BS Forecast'!E11-'BS Forecast'!D11) -> 713.66 | F15: =-('BS Forecast'!G12-'BS Forecast'!E12)-('BS Forecast'!G5-'BS Forecast'!E5)-('BS Forecast'!G6-'BS Forecast'!E6)-('BS Forecast'!G8-'BS Forecast'!E8)-('BS Forecast'!G15-'BS Forecast'!E15)-('BS Forecast'!G9-'BS Forecast'!E9)-('BS Forecast'!G10-'BS Forecast'!E10)-('BS Forecast'!G11-'BS Forecast'!E11) -> -39.504982 | G15: =-('BS Forecast'!H12-'BS Forecast'!G12)-('BS Forecast'!H5-'BS Forecast'!G5)-('BS Forecast'!H6-'BS Forecast'!G6)-('BS Forecast'!H8-'BS Forecast'!G8)-('BS Forecast'!H15-'BS Forecast'!G15)-('BS Forecast'!H9-'BS Forecast'!G9)-('BS Forecast'!H10-'BS Forecast'!G10)-('BS Forecast'!H11-'BS Forecast'!G11) -> -12.778874 | H15: =-('BS Forecast'!I12-'BS Forecast'!H12)-('BS Forecast'!I5-'BS Forecast'!H5)-('BS Forecast'!I6-'BS Forecast'!H6)-('BS Forecast'!I8-'BS Forecast'!H8)-('BS Forecast'!I15-'BS Forecast'!H15)-('BS Forecast'!I9-'BS Forecast'!H9)-('BS Forecast'!I10-'BS Forecast'!H10)-('BS Forecast'!I11-'BS Forecast'!H11) -> 0.79386862 | I15: =-('BS Forecast'!J12-'BS Forecast'!I12)-('BS Forecast'!J5-'BS Forecast'!I5)-('BS Forecast'!J6-'BS Forecast'!I6)-('BS Forecast'!J8-'BS Forecast'!I8)-('BS Forecast'!J15-'BS Forecast'!I15)-('BS Forecast'!J9-'BS Forecast'!I9)-('BS Forecast'!J10-'BS Forecast'!I10)-('BS Forecast'!J11-'BS Forecast'!I11) -> -26.751979 | J15: =-('BS Forecast'!K12-'BS Forecast'!J12)-('BS Forecast'!K5-'BS Forecast'!J5)-('BS Forecast'!K6-'BS Forecast'!J6)-('BS Forecast'!K8-'BS Forecast'!J8)-('BS Forecast'!K15-'BS Forecast'!J15)-('BS Forecast'!K9-'BS Forecast'!J9)-('BS Forecast'!K10-'BS Forecast'!J10)-('BS Forecast'!K11-'BS Forecast'!J11) -> -9.0892168
B16: other liabilities | C16: =('BS Forecast'!D22-'BS Forecast'!C22) -> 45.53 | D16: ='BS Forecast'!E22-'BS Forecast'!D22 -> 13.44 | F16: ='BS Forecast'!G22-'BS Forecast'!E22 -> -1.2211773 | G16: ='BS Forecast'!H22-'BS Forecast'!G22 -> 9.1684627 | H16: ='BS Forecast'!I22-'BS Forecast'!H22 -> 9.5476157 | I16: ='BS Forecast'!J22-'BS Forecast'!I22 -> 9.9413141 | J16: ='BS Forecast'!K22-'BS Forecast'!J22 -> 10.350171
B17: Capex | C17: =-'PP&E schedule'!D7 -> -1087.9 | D17: =-'PP&E schedule'!E7 -> -416.02 | F17: =-'PP&E schedule'!F7 -> -443.15805 | G17: =-'PP&E schedule'!G7 -> -466.56417 | H17: =-'PP&E schedule'!H7 -> -491.20653 | I17: =-'PP&E schedule'!I7 -> -517.15041 | J17: =-'PP&E schedule'!J7 -> -544.46456
B18: Exceptional Items | C18: ='P&L Forecast'!D18 -> 227.74 | D18: ='P&L Forecast'!E18 -> -2.9 | F18: ='P&L Forecast'!G18 -> 0 | G18: ='P&L Forecast'!H18 -> 0 | H18: ='P&L Forecast'!I18 -> 0 | I18: ='P&L Forecast'!J18 -> 0 | J18: ='P&L Forecast'!K18 -> 0
B19: UFCF (Unlevered Free Cash Flow) | C19: =SUM(C14:C17,C9,C18,) -> 847.78049 | D19: =SUM(D14:D17,D9,D18) -> 2908.8582 | F19: =SUM(F14:F17,F9,F18) -> 1989.9896 | G19: =SUM(G14:G17,G9,G18) -> 2234.4959 | H19: =SUM(H14:H17,H9,H18) -> 2330.5809 | I19: =SUM(I14:I17,I9,I18) -> 2388.7167 | J19: =SUM(J14:J17,J9,J18) -> 2495.3375
B20: Interest Expenses | C20: ='P&L Forecast'!D17 -> -154.95 | D20: ='P&L Forecast'!E17 -> -151.4 | F20: ='P&L Forecast'!G17 -> -87.3216 | G20: ='P&L Forecast'!H17 -> -81.574084 | H20: ='P&L Forecast'!I17 -> -75.309292 | I20: ='P&L Forecast'!J17 -> -68.480669 | J20: ='P&L Forecast'!K17 -> -61.03747
B21: Delta Taxes vs. Operating taxes | C21: ='P&L Forecast'!D20-'Cash Flow Forecast'!C6 -> -17.96049 | D21: ='P&L Forecast'!E20-'Cash Flow Forecast'!D6 -> 41.791835 | F21: ='P&L Forecast'!G20-'Cash Flow Forecast'!F6 -> 22.703616 | G21: ='P&L Forecast'!H20-'Cash Flow Forecast'!G6 -> 21.209262 | H21: ='P&L Forecast'!I20-'Cash Flow Forecast'!H6 -> 19.580416 | I21: ='P&L Forecast'!J20-'Cash Flow Forecast'!I6 -> 17.804974 | J21: ='P&L Forecast'!K20-'Cash Flow Forecast'!J6 -> 15.869742
B22: Delta Financial liabilities | C22: =('BS Forecast'!D20-'BS Forecast'!C20)+('BS Forecast'!D19-'BS Forecast'!C19) -> 627.24 | D22: =('BS Forecast'!E20-'BS Forecast'!D20)+('BS Forecast'!E19-'BS Forecast'!D19) -> -874.14 | F22: =('BS Forecast'!G20-'BS Forecast'!E20)+('BS Forecast'!G19-'BS Forecast'!E19) -> -221.07228 | G22: =('BS Forecast'!H20-'BS Forecast'!G20)+('BS Forecast'!H19-'BS Forecast'!G19) -> -211.0987 | H22: =('BS Forecast'!I20-'BS Forecast'!H20)+('BS Forecast'!I19-'BS Forecast'!H19) -> -203.2145 | I22: =('BS Forecast'!J20-'BS Forecast'!I20)+('BS Forecast'!J19-'BS Forecast'!I19) -> -197.30903 | J22: =('BS Forecast'!K20-'BS Forecast'!J20)+('BS Forecast'!K19-'BS Forecast'!J19) -> -193.29155
B23: Delta Provisions | C23: =('BS Forecast'!D23-'BS Forecast'!C23) -> 57.7 | D23: =('BS Forecast'!E23-'BS Forecast'!D23) -> 42.33 | F23: =('BS Forecast'!G23-'BS Forecast'!E23) -> 58.172176 | G23: =('BS Forecast'!H23-'BS Forecast'!G23) -> 64.311624 | H23: =('BS Forecast'!I23-'BS Forecast'!H23) -> 71.099024 | I23: =('BS Forecast'!J23-'BS Forecast'!I23) -> 78.602761 | J23: =('BS Forecast'!K23-'BS Forecast'!J23) -> 86.898437
B24: Delta Equity inc dividend | C24: ='BS Forecast'!D26-'BS Forecast'!C26-'P&L Forecast'!D21 -> -1360.69 | D24: ='BS Forecast'!E26-'BS Forecast'!D26-'P&L Forecast'!E21 -> -1735.68 | F24: ='BS Forecast'!G26-'BS Forecast'!E26-'P&L Forecast'!G21 -> -1554.5488 | G24: ='BS Forecast'!H26-'BS Forecast'!G26-'P&L Forecast'!H21 -> -1617.5433 | H24: ='BS Forecast'!I26-'BS Forecast'!H26-'P&L Forecast'!I21 -> -1683.1879 | I24: ='BS Forecast'!J26-'BS Forecast'!I26-'P&L Forecast'!J21 -> -1751.5915 | J24: ='BS Forecast'!K26-'BS Forecast'!J26-'P&L Forecast'!K21 -> -1822.8684
B25: Net Cash Flow | C25: =SUM(C19:C24) -> -0.88 | D25: =SUM(D19:D24) -> 231.76 | F25: =SUM(F19:F24) -> 207.92278 | G25: =SUM(G19:G24) -> 409.80071 | H25: =SUM(H19:H24) -> 459.54864 | I25: =SUM(I19:I24) -> 467.74326 | J25: =SUM(J19:J24) -> 520.90825
B27: opening cash | C27: ='BS Forecast'!C16 -> 9.97 | D27: ='BS Forecast'!D16 -> 9.09 | F27: ='BS Forecast'!E16 -> 240.85 | G27: ='BS Forecast'!G16 -> 448.77278 | H27: ='BS Forecast'!H16 -> 858.57349 | I27: ='BS Forecast'!I16 -> 1318.1221 | J27: ='BS Forecast'!J16 -> 1785.8654
B28: closing cash | C28: =C27+C25 -> 9.09 | D28: =D27+D25 -> 240.85 | F28: =F25+F27 -> 448.77278 | G28: =G25+G27 -> 858.57349 | H28: =H25+H27 -> 1318.1221 | I28: =I25+I27 -> 1785.8654 | J28: =J25+J27 -> 2306.7736
B30: check | C30: ='BS Forecast'!D16 -> 9.09 | D30: ='BS Forecast'!E16 -> 240.85 | F30: ='BS Forecast'!G16 -> 448.77278 | G30: ='BS Forecast'!H16 -> 858.57349 | H30: ='BS Forecast'!I16 -> 1318.1221 | I30: ='BS Forecast'!J16 -> 1785.8654 | J30: ='BS Forecast'!K16 -> 2306.7736
C31: =C28-C30 -> -3.3573144e-13 | D31: =D30-D28 -> -2.2737368e-13 | F31: =F30-F28 -> 0 | G31: =G30-G28 -> 0 | H31: =H30-H28 -> 0 | I31: =I30-I28 -> 0 | J31: =J30-J28 -> 0

Sheet WACC
B1: WACC
B3: Risk free rate | C3: 0.0675
B4: market Risk premium | C4: 0.06
B5: Beta | C5: 0.62
B6: Tax Rate | C6: 0.3
B7: current bond yeild | C7: 0.055
B8: Cost of Equity | C8: =C3+C4*C5 -> 0.1047
B11: In Crores | C11: 2022 | D11: 2023 | E11: 2024 | G11: 2025 | H11: 2026 | I11: 2027 | J11: 2028 | K11: 2029
B12: Debt | C12: ='BS Forecast'!C19+'BS Forecast'!C20 -> 2789.25 | D12: ='BS Forecast'!D19+'BS Forecast'!D20 -> 3416.49 | E12: ='BS Forecast'!E19+'BS Forecast'!E20 -> 2542.35 | G12: ='BS Forecast'!G19+'BS Forecast'!G20 -> 2321.2777 | H12: ='BS Forecast'!H19+'BS Forecast'!H20 -> 2110.179 | I12: ='BS Forecast'!I19+'BS Forecast'!I20 -> 1906.9645 | J12: ='BS Forecast'!J19+'BS Forecast'!J20 -> 1709.6555 | K12: ='BS Forecast'!K19+'BS Forecast'!K20 -> 1516.3639
B13: Equity | C13: ='BS Forecast'!C26 -> 2402.54 | D13: ='BS Forecast'!D26 -> 3181.15 | E13: ='BS Forecast'!E26 -> 3527.52 | G13: ='BS Forecast'!G26 -> 4193.7552 | H13: ='BS Forecast'!H26 -> 4886.988 | I13: ='BS Forecast'!I26 -> 5608.3543 | J13: ='BS Forecast'!J26 -> 6359.0363 | K13: ='BS Forecast'!K26 -> 7140.2656
B15: Debt/(Debt+Equity) | C15: =C12/(C12+C13) -> 0.53724245 | D15: =D12/(D12+D13) -> 0.51783517 | E15: =E12/(E12+E13) -> 0.41884752 | G15: =G12/(G12+G13) -> 0.35629562 | H15: =H12/(H12+H13) -> 0.3015762 | I15: =I12/(I12+I13) -> 0.25374366 | J15: =J12/(J12+J13) -> 0.21188757 | K15: =K12/(K12+K13) -> 0.17516794
B16: Equity/(Debt+Equity) | C16: =C13/(C12+C13) -> 0.46275755 | D16: =D13/(D12+D13) -> 0.48216483 | E16: =E13/(E12+E13) -> 0.58115248 | G16: =G13/(G12+G13) -> 0.64370438 | H16: =H13/(H12+H13) -> 0.6984238 | I16: =I13/(I12+I13) -> 0.74625634 | J16: =J13/(J12+J13) -> 0.78811243 | K16: =K13/(K12+K13) -> 0.82483206
B18: Cost of Equity | C18: =$C$8 -> 0.1047 | D18: =$C$8 -> 0.1047 | E18: =$C$8 -> 0.1047 | G18: =$C$8 -> 0.1047 | H18: =$C$8 -> 0.1047 | I18: =$C$8 -> 0.1047 | J18: =$C$8 -> 0.1047 | K18: =$C$8 -> 0.1047
B19: Cost of Debt | C19: =$C$7 -> 0.055 | D19: =$C$7 -> 0.055 | E19: =$C$7 -> 0.055 | G19: =$C$7 -> 0.055 | H19: =$C$7 -> 0.055 | I19: =$C$7 -> 0.055 | J19: =$C$7 -> 0.055 | K19: =$C$7 -> 0.055
B21: WACC | C21: =C19*C15*(1-C6)+C18*C16 -> 0.06913455 | D21: =D19*D15*(1-D6)+D18*D16 -> 0.078963592 | E21: =E19*E15*(1-E6)+E18*E16 -> 0.083883278 | G21: =G19*G15*(1-G6)+G18*G16 -> 0.086992107 | H21: =H19*H15*(1-H6)+H18*H16 -> 0.089711663 | I21: =I19*I15*(1-I6)+I18*I16 -> 0.09208894 | J21: =J19*J15*(1-J6)+J18*J16 -> 0.094169188 | K21: =K19*K15*(1-K6)+K18*K16 -> 0.095994154

Sheet DCF 
B1: Discounted Cash Flow
B3: *Click g for sensitivity Analysis
B4: g (Growth rate) | C4: 0.08
D5: 1 | E5: 2 | F5: 3 | G5: 4 | H5: 5 | BB5: 0.075 | BC5: 0.08 | BD5: 0.085
B6: In Crores | D6: 2025 | E6: 2026 | F6: 2027 | G6: 2028 | H6: 2029
B7: UFCF | D7: ='Cash Flow Forecast'!F19 -> 1989.9896 | E7: ='Cash Flow Forecast'!G19 -> 2234.4959 | F7: ='Cash Flow Forecast'!H19 -> 2330.5809 | G7: ='Cash Flow Forecast'!I19 -> 2388.7167 | H7: ='Cash Flow Forecast'!J19 -> 2495.3375
B8: Terminal Value | H8: =H7*(1+C4)/(H9-C4) -> 168496.85
B9: Discounting Factor | D9: =WACC!G21 -> 0.086992107 | E9: =WACC!H21 -> 0.089711663 | F9: =WACC!I21 -> 0.09208894 | G9: =WACC!J21 -> 0.094169188 | H9: =WACC!K21 -> 0.095994154
B10: Present value of UFCF | D10: =D7/(1+D9)^D5 -> 1830.7305 | E10: =E7/(1+E9)^E5 -> 1881.7259 | F10: =F7/(1+F9)^F5 -> 1789.3288 | G10: =G7/(1+G9)^G5 -> 1666.5821 | H10: =H7/(1+H9)^H5 -> 1577.9313
B13: *In Crores
B14: Sum of PV of UFCF | C14: =SUM(D10:H10) -> 8746.2987
B15: present value of TV | C15: =H8/(1+H9)^H5 -> 106549.3
B16: Enterprise Value | C16: =C14+C15 -> 115295.6
B17: Net Debt | C17: =('BS Forecast'!E20+'BS Forecast'!E19)-'Cash Flow'!E8 -> 2301.5
B18: Equity Value | C18: =C16-C17 -> 112994.1
B19: Total Share Outstanding | C19: ='P&L'!E31 -> 24.08
B20: Instrinsic Share Price | C20: =C18/C19 -> 4692.4459
B21: Actual Share Price | C21: ='Britannia Stock Data'!B13 -> 5866
B22: =IF(C21>C20,"Overvalued","Undervalued") -> Overvalued | C22: =C21/C20-1 -> 0.25009433
B23: BUY/HOLD/SELL | C23: =IF(ABS(C21-C20) <= 500, "HOLD", IF(C21> C20, "SELL", "BUY")) -> SELL

Sheet Equity Schedule
B1: Equity Schedule
F4: forecast
B5: $ in million | C5: 44926 | D5: 45291 | E5: 45657 | F5: 46022 | G5: 46387 | H5: 46752 | I5: 47118 | J5: 47483
B6: beginning equity | F6: =E10 -> 3527.52 | G6: =F10 -> 4193.7552 | H6: =G10 -> 4886.988 | I6: =H10 -> 5608.3543 | J6: =I10 -> 6359.0363
B7: inrease in capital | F7: 0 | G7: 0 | H7: 0 | I7: 0 | J7: 0
B8: net income(loss) | F8: ='P&L Forecast'!G21 -> 2220.7839 | G8: ='P&L Forecast'!H21 -> 2310.7761 | H8: ='P&L Forecast'!I21 -> 2404.5541 | I8: ='P&L Forecast'!J21 -> 2502.2735 | J8: ='P&L Forecast'!K21 -> 2604.0977
B9: dividends | F9: =-IF(F8<0,0,F8*F12) -> -1554.5488 | G9: =-IF(G8<0,0,G8*G12) -> -1617.5433 | H9: =-IF(H8<0,0,H8*H12) -> -1683.1879 | I9: =-IF(I8<0,0,I8*I12) -> -1751.5915 | J9: =-IF(J8<0,0,J8*J12) -> -1822.8684
B10: ending equity | E10: ='BS Forecast'!E26 -> 3527.52 | F10: =SUM(F6:F9) -> 4193.7552 | G10: =SUM(G6:G9) -> 4886.988 | H10: =SUM(H6:H9) -> 5608.3543 | I10: =SUM(I6:I9) -> 6359.0363 | J10: =SUM(J6:J9) -> 7140.2656
B12: dividends as% of net income ( as per Financial Reports) | F12: 0.7 | G12: 0.7 | H12: 0.7 | I12: 0.7 | J12: 0.7

Sheet financial liabilites
B1: Financial Liabilities
F4: forecast
B5: $ in million | C5: 44926 | D5: 45291 | E5: 45657 | F5: 46022 | G5: 46387 | H5: 46752 | I5: 47118 | J5: 47483
B6: beginning debt | D6: =C9 -> 750.94 | E6: =D9 -> 1611.93 | F6: =E9 -> 970.24 | G6: =F9 -> 906.37872 | H6: =G9 -> 836.76992 | I6: =H9 -> 760.89632 | J6: =I9 -> 678.19411
B7: new debt | D7: =IF(D9<C9,0,D9-C9) -> 860.99 | E7: =IF(E9<D9,0,E9-D9) -> 0 | F7: =100 -> 100 | G7: =100 -> 100 | H7: =100 -> 100 | I7: =100 -> 100 | J7: =100 -> 100
B8: principals repayments | D8: =IF(D9>C9,0,D9-C9) -> 0 | E8: =IF(E9>D9,0,E9-D9) -> -641.69 | F8: =C20 -> -63.861284 | G8: =D20 -> -69.6088 | H8: =E20 -> -75.873592 | I8: =F20 -> -82.702215 | J8: =G20 -> -90.145414
B9: Ending debt | C9: ='BS Forecast'!C20 -> 750.94 | D9: ='BS Forecast'!D20 -> 1611.93 | E9: ='BS Forecast'!E20 -> 970.24 | F9: =C21 -> 906.37872 | G9: =D21 -> 836.76992 | H9: =E21 -> 760.89632 | I9: =F21 -> 678.19411 | J9: =G21 -> 588.0487
B11: debt to be repaid in Yr. | C11: 10
B12: interest | C12: 0.09
B13: annual payment | C13: =PMT(C12,C11,E9) -> -151.18288
B17: period | C17: 1 | D17: 2 | E17: 3 | F17: 4 | G17: 5 | H17: 6 | I17: 7 | J17: 8 | K17: 9 | L17: 10
B18: payment | C18: =$C$13 -> -151.18288 | D18: =$C$13 -> -151.18288 | E18: =$C$13 -> -151.18288 | F18: =$C$13 -> -151.18288 | G18: =$C$13 -> -151.18288 | H18: =$C$13 -> -151.18288 | I18: =$C$13 -> -151.18288 | J18: =$C$13 -> -151.18288 | ... L18: =$C$13 -> -151.18288
B19: interest expense | C19: =-(E9*C12) -> -87.3216 | D19: =-(C21*$C$12) -> -81.574084 | E19: =-(D21*$C$12) -> -75.309292 | F19: =-(E21*$C$12) -> -68.480669 | G19: =-(F21*$C$12) -> -61.03747 | H19: =-(G21*$C$12) -> -52.924383 | I19: =-(H21*$C$12) -> -44.081118 | J19: =-(I21*$C$12) -> -34.441959 | K19: =-(J21*$C$12) -> -23.935275 | L19: =-(K21*$C$12) -> -12.48299
B20: debt repayment | C20: =C18-C19 -> -63.861284 | D20: =D18-D19 -> -69.6088 | E20: =E18-E19 -> -75.873592 | F20: =F18-F19 -> -82.702215 | G20: =G18-G19 -> -90.145414 | H20: =H18-H19 -> -98.258501 | I20: =I18-I19 -> -107.10177 | J20: =J18-J19 -> -116.74093 | ... L20: =L18-L19 -> -138.69989
B21: residual debt | C21: =E$9+C$20 -> 906.37872 | D21: =C21+D20 -> 836.76992 | E21: =D21+E20 -> 760.89632 | F21: =E21+F20 -> 678.19411 | G21: =F21+G20 -> 588.0487 | H21: =G21+H20 -> 489.79019 | I21: =H21+I20 -> 382.68843 | J21: =I21+J20 -> 265.9475 | K21: =J21+K20 -> 138.69989 | L21: =K21+L20 -> 2.5579538e-13

Sheet PP&E schedule
B1: PP&E Schedule
F3: forecast
B4: $ in million | C4: 44926 | D4: 45291 | E4: 45657 | F4: 46022 | G4: 46387 | H4: 46752 | I4: 47118 | J4: 47483
B5: beginning PPE | D5: =C8 -> 1327.41 | E5: ='BS Forecast'!D7 -> 2220.21 | F5: =E8 -> 2365.04 | G5: =F8 -> 2489.9535 | H5: =G8 -> 2621.4645 | I5: =H8 -> 2759.9214 | J5: =I8 -> 2905.6912
B6: D&A | D6: ='P&L Forecast'!D15 -> -195.1 | E6: ='P&L Forecast'!E15 -> -271.19 | F6: =F5*F10 -> -318.24457 | G6: =G5*G10 -> -335.05319 | H6: =H5*H10 -> -352.74957 | I6: =I5*I10 -> -371.38062 | J6: =J5*J10 -> -390.9957
B7: Capex | D7: =D8-D6-D5 -> 1087.9 | E7: =E8-E6-E5 -> 416.02 | F7: =F5*F11 -> 443.15805 | G7: =G5*G11 -> 466.56417 | H7: =H5*H11 -> 491.20653 | I7: =I5*I11 -> 517.15041 | J7: =J5*J11 -> 544.46456
B8: Ending PPE | C8: ='BS Forecast'!C7 -> 1327.41 | D8: ='BS Forecast'!D7 -> 2220.21 | E8: ='BS Forecast'!E7 -> 2365.04 | F8: =SUM(F5:F7) -> 2489.9535 | G8: =SUM(G5:G7) -> 2621.4645 | H8: =SUM(H5:H7) -> 2759.9214 | I8: =SUM(I5:I7) -> 2905.6912 | J8: =SUM(J5:J7) -> 3059.1601
B10: D&A as %of beginning ppe | D10: =D6/D5 -> -0.14697795 | E10: =E6/E5 -> -0.1221461 | F10: =AVERAGE($D$10:$E$10) -> -0.13456203 | G10: =AVERAGE($D$10:$E$10) -> -0.13456203 | H10: =AVERAGE($D$10:$E$10) -> -0.13456203 | I10: =AVERAGE($D$10:$E$10) -> -0.13456203 | J10: =AVERAGE($D$10:$E$10) -> -0.13456203 | K10: taken as avg
B11: capex as % of beginning ppe | D11: =D7/D5 -> 0.81956592 | E11: =E7/E5 -> 0.18737867 | F11: =$E$11 -> 0.18737867 | G11: =$E$11 -> 0.18737867 | H11: =$E$11 -> 0.18737867 | I11: =$E$11 -> 0.18737867 | J11: =$E$11 -> 0.18737867 | K11: taken as last yr only due to unstable capex

Sheet Charts 

Sheet Revenues&EBITDA
B1: Revenue & EBITDA Chart
C3: ACTUAL | G3: FORECAST
B4: In Crores | C4: FY22 | D4: FY23 | E4: FY24 | G4: FY25 | H4: FY26 | I4: FY27 | J4: FY28 | K4: FY29
B5: Revenue | C5: ='P&L Forecast'!C10 -> 13731.05 | D5: ='P&L Forecast'!D10 -> 15839.01 | E5: ='P&L Forecast'!E10 -> 16396.19 | G5: ='P&L Forecast'!G10 -> 17033.128 | H5: ='P&L Forecast'!H10 -> 17696.488 | I5: ='P&L Forecast'!I10 -> 18387.282 | J5: ='P&L Forecast'!J10 -> 19106.56 | K5: ='P&L Forecast'!K10 -> 19855.42
B6: EBITDA | C6: ='P&L Forecast'!C14 -> 2448.59 | D6: ='P&L Forecast'!D14 -> 2962.38 | E6: ='P&L Forecast'!E14 -> 3280.93 | G6: ='P&L Forecast'!G14 -> 3406.6255 | H6: ='P&L Forecast'!H14 -> 3539.2977 | I6: ='P&L Forecast'!I14 -> 3677.4564 | J6: ='P&L Forecast'!J14 -> 3821.312 | K6: ='P&L Forecast'!K14 -> 3971.0841
B7: EBITDA% | C7: =C6/C5 -> 0.17832504 | D7: =D6/D5 -> 0.18703063 | E7: =E6/E5 -> 0.20010319 | G7: =G6/G5 -> 0.2 | H7: =H6/H5 -> 0.2 | I7: =I6/I5 -> 0.2 | J7: =J6/J5 -> 0.2 | K7: =K6/K5 -> 0.2

Sheet Working Capital
B1: Working Capital
B3: In Crores | C3: FY22 | D3: FY23 | E3: FY24 | G3: FY25 | H3: FY26 | I3: FY27 | J3: FY28 | K3: FY29
B4: Inventory | C4: ='BS Forecast'!C13 -> 1251.64 | D4: ='BS Forecast'!D13 -> 1074.62 | E4: ='BS Forecast'!E13 -> 1075.44 | G4: ='BS Forecast'!G13 -> 1126.8963 | H4: ='BS Forecast'!H13 -> 1170.7836 | I4: ='BS Forecast'!I13 -> 1216.4859 | J4: ='BS Forecast'!J13 -> 1264.0727 | K4: ='BS Forecast'!K13 -> 1313.6166
B5: Trade Recieveable | C5: ='BS Forecast'!C14 -> 253.85 | D5: ='BS Forecast'!D14 -> 278.42 | E5: ='BS Forecast'!E14 -> 347.05 | G5: ='BS Forecast'!G14 -> 360.53174 | H5: ='BS Forecast'!H14 -> 374.57277 | I5: ='BS Forecast'!I14 -> 389.19445 | J5: ='BS Forecast'!J14 -> 404.41906 | K5: ='BS Forecast'!K14 -> 420.26981
B6: Trade Payable | C6: ='BS Forecast'!C21 -> 1194.21 | D6: ='BS Forecast'!D21 -> 1308.76 | E6: ='BS Forecast'!E21 -> 1513.14 | G6: ='BS Forecast'!G21 -> 1448.3054 | H6: ='BS Forecast'!H21 -> 1504.7101 | I6: ='BS Forecast'!I21 -> 1563.4474 | J6: ='BS Forecast'!J21 -> 1624.6067 | K6: ='BS Forecast'!K21 -> 1688.2813
B7: Working Capital | C7: =C4+C5-C6 -> 311.28 | D7: =D4+D5-D6 -> 44.28 | E7: =E4+E5-E6 -> -90.65 | G7: =G4+G5-G6 -> 39.12265 | H7: =H4+H5-H6 -> 40.646294 | I7: =I4+I5-I6 -> 42.232947 | J7: =J4+J5-J6 -> 43.885027 | K7: =K4+K5-K6 -> 45.605051
B9: DSO | C9: =(C5/'P&L Forecast'!C10)*360 -> 6.6554269 | D9: =(D5/'P&L Forecast'!D10)*360 -> 6.3281228 | E9: =(E5/'P&L Forecast'!E10)*360 -> 7.619941 | G9: =(G5/'P&L Forecast'!G10)*360 -> 7.619941 | H9: =(H5/'P&L Forecast'!H10)*360 -> 7.619941 | I9: =(I5/'P&L Forecast'!I10)*360 -> 7.619941 | J9: =(J5/'P&L Forecast'!J10)*360 -> 7.619941 | K9: =(K5/'P&L Forecast'!K10)*360 -> 7.619941
B10: DPO | C10: =-(C6/'P&L Forecast'!C11)*360 -> 50.722956 | D10: =-(D6/'P&L Forecast'!D11)*360 -> 49.829155 | E10: =-(E6/'P&L Forecast'!E11)*360 -> 57.777264 | G10: =-(G6/'P&L Forecast'!G11)*360 -> 52.776458 | H10: =-(H6/'P&L Forecast'!H11)*360 -> 52.776458 | I10: =-(I6/'P&L Forecast'!I11)*360 -> 52.776458 | J10: =-(J6/'P&L Forecast'!J11)*360 -> 52.776458 | K10: =-(K6/'P&L Forecast'!K11)*360 -> 52.776458
B11: DIO | C11: =-(C4/'P&L Forecast'!C11)*360 -> 53.162241 | D11: =-(D4/'P&L Forecast'!D11)*360 -> 40.914612 | E11: =-(E4/'P&L Forecast'!E11)*360 -> 41.064264 | G11: =-(G4/'P&L Forecast'!G11)*360 -> 41.064264 | H11: =-(H4/'P&L Forecast'!H11)*360 -> 41.064264 | I11: =-(I4/'P&L Forecast'!I11)*360 -> 41.064264 | J11: =-(J4/'P&L Forecast'!J11)*360 -> 41.064264 | K11: =-(K4/'P&L Forecast'!K11)*360 -> 41.064264

Sheet historical data 

Sheet P&L
B1: Income Statement
C2: ACTUAL
B3: (in crores) | C3: 44651 | D3: 45016 | E3: 45382
B4: Sale of goods | C4: 13169.04 | D4: 15285.12 | E4: 15938.87
B5: Other operating revenues | C5: 202.58 | D5: 333.3 | E5: 247.21
B6: Revenue from operations | C6: =SUM(C4:C5) -> 13371.62 | D6: =SUM(D4:D5) -> 15618.42 | E6: =SUM(E4:E5) -> 16186.08
B7: Other income | C7: 359.43 | D7: 220.59 | E7: 210.11
A8: I | B8: Total Revenue | C8: =C6+C7 -> 13731.05 | D8: =D6+D7 -> 15839.01 | E8: =E6+E7 -> 16396.19
A9: II | B9: Cost of materials consumed | C9: 6366.31 | D9: 7084.09 | E9: 7394.74
A10: III | B10: Purchases of stock-in-trade | C10: 2183.41 | D10: 2453.42 | E10: 2033.36
A11: IV | B11: Changes in inventories of finished goods, work-in-progress and stock- in-trade | C11: -73.96 | D11: -82.13 | E11: 0.01
A12: V | B12: Cost Of Goods Sold | C12: =SUM(C9:C11) -> 8475.76 | D12: =SUM(D9:D11) -> 9455.38 | E12: =SUM(E9:E11) -> 9428.11
B13: Gross Profit (I-V) | C13: =C8-C12 -> 5255.29 | D13: =D8-D12 -> 6383.63 | E13: =E8-E12 -> 6968.08
B14: Other expenses | C14: -2393.14 | D14: -2900.7 | E14: -3121.87
B15: Employee benefits expense | C15: -413.56 | D15: -520.55 | E15: -565.28
B16: EBITDA | C16: =SUM(C13:C15) -> 2448.59 | D16: =SUM(D13:D15) -> 2962.38 | E16: =SUM(E13:E15) -> 3280.93
B17: Depreciation and amortisation expense | C17: -170.01 | D17: -195.1 | E17: -271.19
B18: Interest Expenses | C18: -133.46 | D18: -154.95 | E18: -151.4
B19: EBIT | C19: =SUM(C16:C18) -> 2145.12 | D19: =SUM(D16:D18) -> 2612.33 | E19: =SUM(E16:E18) -> 2858.34
B20: Exceptional items | C20: 0 | D20: 227.74 | E20: -2.9
B21: Profit before tax | C21: =SUM(C19:C20) -> 2145.12 | D21: =SUM(D19:D20) -> 2840.07 | E21: =SUM(E19:E20) -> 2855.44
B22: Tax expense (credit)
B23: (i) Current tax | C23: 590.36 | D23: 708.5 | E23: 760.7
B24: (ii) Deferred tax ( ) | C24: -48.43 | D24: -7.73 | E24: 12.69
C25: =SUM(C23:C24) -> 541.93 | D25: =SUM(D23:D24) -> 700.77 | E25: =SUM(E23:E24) -> 773.39
A26: VI | B26: Profit After Tax (PAT) | C26: =C21-C25 -> 1603.19 | D26: =D21-D25 -> 2139.3 | E26: =E21-E25 -> 2082.05
A27: VII | B27: Other comprehensive (loss) income, net of tax ( ) | C27: 0.49 | D27: 0.22 | E27: -1.43
B28: Total comprehensive income for the year (VI-VII) | C28: =C26+C27 -> 1603.68 | D28: =D26+D27 -> 2139.52 | E28: =E26+E27 -> 2080.62
B30: No. of Shares
B31: Basic | C31: 24.08 | D31: 24.08 | E31: 24.08
B32: Diluted | C32: 24.08 | D32: 24.08 | E32: 24.08
B34: Earning Per Share (face value as 1)
B35: Basic | C35: =C$28/C31 -> 66.598007 | D35: =D$28/D31 -> 88.850498 | E35: =E$28/E31 -> 86.404485
B36: Dilueted | C36: =C$28/C32 -> 66.598007 | D36: =D$28/D32 -> 88.850498 | E36: =E$28/E32 -> 86.404485

Sheet BS
B1: Balance sheet
C2: ACTUAL
B3: (in crores) | C3: 44651 | D3: 45016 | E3: 45382
A4: I | B4: Assets
B5: (1) Non-current assets
B6: (a) Property, plant and equipment | C6: 1327.41 | D6: 2220.21 | E6: 2365.04
B7: (b) Capital work-in-progress | C7: 535.27 | D7: 104.47 | E7: 187.48
B8: (c) Investment property | C8: 34.42 | D8: 60.5 | E8: 46.75
B9: (e) Other Intangible assets | C9: 15.6 | D9: 12.75 | E9: 9.38
B10: (g) Financial assets | C10: =SUM(C11:C13) -> 1334.74 | D10: =SUM(D11:D13) -> 1688.14 | E10: =SUM(E11:E13) -> 1093.29
B11: (i) Investments | C11: 1221.61 | D11: 1525.18 | E11: 1080.04
B12: (ii) Loans receivable | C12: 100 | D12: 150 | E12: 0
B13: (iii) Other financial assets | C13: 13.13 | D13: 12.96 | E13: 13.25
B14: (f) Deferred tax assets (net) | C14: 40.58 | D14: 48.31 | E14: 35.62
B15: (g) Tax assets (net) | C15: 27.54 | D15: 39.63 | E15: 60.03
B16: (h) Other non-current assets | C16: 94.33 | D16: 43.75 | E16: 53.54
B17: Total non-current assets | C17: =SUM(C6:C10,C14:C16) -> 3409.89 | D17: =SUM(D6:D10,D14:D16) -> 4217.76 | E17: =SUM(E6:E10,E14:E16) -> 3851.13
B18: (2) Current assets
B19: (a) Inventories | C19: 1251.64 | D19: 1074.62 | E19: 1075.44
B20: (b) Financial assets | C20: =C21+C24+C25+C26 -> 1969.19 | D20: =D21+D24+D25+D26 -> 2863.13 | E20: =E21+E24+E25+E26 -> 2728.91
B21: (i) Investments | C21: 802.5 | D21: 1798.47 | E21: 1690.68
B22: (ii) Trade receivables | C22: 253.85 | D22: 278.42 | E22: 347.05
B23: (iii) Cash and cash equivalents | C23: 9.97 | D23: 9.09 | E23: 240.85
B24: (iv) Bank balances other than (iii) above | C24: 42.32 | D24: 54.76 | E24: 56.65
B25: (v) Loans receivable | C25: 698 | D25: 560 | E25: 460
B26: (vi) Other financial assets | C26: 426.37 | D26: 449.9 | E26: 521.58
B27: (c) Other current assets | C27: 120.29 | D27: 163.08 | E27: 121.05
B28: (d) Assets held-for-sale | C28: 0 | D28: 32.36 | E28: 6.41
B29: Total current assets | C29: =SUM(C21:C28,C19) -> 3604.94 | D29: =SUM(D21:D28,D19) -> 4420.7 | E29: =SUM(E21:E28,E19) -> 4519.71
B30: Total assets | C30: =C29+C17 -> 7014.83 | D30: =D29+D17 -> 8638.46 | E30: =E29+E17 -> 8370.84
A31: II | B31: Equity and liabilities
B32: (1) Equity
B33: (a) Equity share capital | C33: 24.09 | D33: 24.09 | E33: 24.09
B34: (b) Other equity | C34: 2378.45 | D34: 3157.06 | E34: 3503.43
B35: Total equity | C35: =C34+C33 -> 2402.54 | D35: =D34+D33 -> 3181.15 | E35: =E34+E33 -> 3527.52
B36: (2) Liabilities
B37: (A) Non-current liabilities
B38: (a) Financial liabilities
B39: (i) Borrowings 20 (a) | C39: 698.52 | D39: 1551.02 | E39: 904.17
B40: (ii) Lease liabilities 20 (b) | C40: 0.03 | D40: 0.76 | E40: 0.5
...

Sheet Cash Flow
B1: Cash Flow Statement
B3: In Crores | C3: 2022 | D3: 2023 | E3: 2024
